<?xml version="1.0"?>
<robot xmlns:ns0="http://drake.mit.edu" name="iiwa14">
  <material name="Black">
    <color rgba="0.0 0.0 0.0 1.0" />
  </material>
  <material name="Blue">
    <color rgba="0.0 0.0 0.8 1.0" />
  </material>
  <material name="Green">
    <color rgba="0.0 0.8 0.0 1.0" />
  </material>
  <material name="Grey">
    <color rgba="0.4 0.4 0.4 1.0" />
  </material>
  <material name="Silver">
    <color rgba="0.6 0.6 0.6 1.0" />
  </material>
  <material name="Orange">
    <color rgba="1.0 0.423529411765 0.0392156862745 1.0" />
  </material>
  <material name="Brown">
    <color rgba="0.870588235294 0.811764705882 0.764705882353 1.0" />
  </material>
  <material name="Red">
    <color rgba="0.8 0.0 0.0 1.0" />
  </material>
  <material name="White">
    <color rgba="1.0 1.0 1.0 1.0" />
  </material>
  <link name="base" />
  <joint name="iiwa_base_joint" type="fixed">
    <origin rpy="0 0 0" xyz="0 0 0" />
    <parent link="base" />
    <child link="iiwa_link_0" />
  </joint>
  <link name="iiwa_link_0">
    <inertial>
      <origin rpy="0 0 0" xyz="-0.1 0 0.07" />
      <mass value="5" />
      <inertia ixx="0.05" ixy="0" ixz="0" iyy="0.06" iyz="0" izz="0.03" />
    </inertial>
    <visual name="iiwa_link_0_visual">
      <origin rpy="0 0 0" xyz="0 0 0" />
      <geometry>
        <mesh filename="package://drake/manipulation/models/iiwa_description/meshes/visual/link_0.obj" />
      </geometry>
      <material name="Grey" />
    </visual>
  </link>
  <joint name="iiwa_joint_1" type="revolute">
    <parent link="iiwa_link_0" />
    <child link="iiwa_link_1" />
    <origin rpy="0 0 0" xyz="0 0 0.1575" />
    <axis xyz="0 0 1" />
    <limit ns0:acceleration="8.57" effort="320" lower="-2.96705972839" upper="2.96705972839" velocity="1.4835298641951802" />
    <dynamics damping="0.5" />
  </joint>
  <link name="iiwa_link_1">
    <inertial>
      <origin rpy="0 0 0" xyz="0 -0.03 0.12" />
      <mass value="5.76" />
      <inertia ixx="0.033" ixy="0" ixz="0" iyy="0.0333" iyz="0" izz="0.0123" />
    </inertial>
    <visual name="iiwa_link_1_visual">
      <origin rpy="0 0 0" xyz="0 0 0" />
      <geometry>
        <mesh filename="package://drake/manipulation/models/iiwa_description/meshes/visual/link_1.obj" />
      </geometry>
      <material name="Grey" />
    </visual>
  </link>
  <joint name="iiwa_joint_2" type="revolute">
    <parent link="iiwa_link_1" />
    <child link="iiwa_link_2" />
    <origin rpy="1.570796326794897   0 3.141592653589793" xyz="0 0 0.2025" />
    <axis xyz="0 0 1" />
    <limit ns0:acceleration="8.57" effort="320" lower="-2.09439510239" upper="2.09439510239" velocity="1.4835298641951802" />
    <dynamics damping="0.5" />
  </joint>
  <link name="iiwa_link_2">
    <inertial>
      <origin rpy="0 0 0" xyz="0.0003 0.059 0.042" />
      <mass value="6.35" />
      <inertia ixx="0.0305" ixy="0" ixz="0" iyy="0.0304" iyz="0" izz="0.011" />
    </inertial>
    <visual name="iiwa_link_2_visual">
      <origin rpy="0 0 0" xyz="0 0 0" />
      <geometry>
        <mesh filename="package://drake/manipulation/models/iiwa_description/meshes/visual/link_2_orange.obj" />
      </geometry>
      <material name="Orange" />
    </visual>
    <visual name="iiwa_link_2_visual">
      <origin rpy="0 0 0" xyz="0 0 0" />
      <geometry>
        <mesh filename="package://drake/manipulation/models/iiwa_description/meshes/visual/link_2_grey.obj" />
      </geometry>
      <material name="Grey" />
    </visual>
  </link>
  <joint name="iiwa_joint_3" type="revolute">
    <parent link="iiwa_link_2" />
    <child link="iiwa_link_3" />
    <origin rpy="1.570796326794897 0 3.141592653589793" xyz="0 0.2045 0" />
    <axis xyz="0 0 1" />
    <limit ns0:acceleration="8.74" effort="176" lower="-2.96705972839" upper="2.96705972839" velocity="1.7453292519943295" />
    <dynamics damping="0.5" />
  </joint>
  <link name="iiwa_link_3">
    <inertial>
      <origin rpy="0 0 0" xyz="0 0.03 0.13" />
      <mass value="3.5" />
      <inertia ixx="0.025" ixy="0" ixz="0" iyy="0.0238" iyz="0" izz="0.0076" />
    </inertial>
    <visual name="iiwa_link_3_visual">
      <origin rpy="0 0 0" xyz="0 0 0" />
      <geometry>
        <mesh filename="package://drake/manipulation/models/iiwa_description/meshes/visual/link_3.obj" />
      </geometry>
      <material name="Grey" />
    </visual>
    <visual name="iiwa_link_3_visual">
      <origin rpy="0 0 0" xyz="0 0 0" />
      <geometry>
        <mesh filename="package://drake/manipulation/models/iiwa_description/meshes/visual/kuka.obj" />
      </geometry>
      <material name="Black" />
    </visual>
    <visual name="iiwa_link_3_visual">
      <origin rpy="0 0 0" xyz="0 0 0" />
      <geometry>
        <mesh filename="package://drake/manipulation/models/iiwa_description/meshes/visual/band.obj" />
      </geometry>
      <material name="Silver" />
    </visual>
  </link>
  <joint name="iiwa_joint_4" type="revolute">
    <parent link="iiwa_link_3" />
    <child link="iiwa_link_4" />
    <origin rpy="1.570796326794897 0 0" xyz="0 0 0.2155" />
    <axis xyz="0 0 1" />
    <limit ns0:acceleration="11.36" effort="176" lower="-2.09439510239" upper="2.09439510239" velocity="1.3089969389957472" />
    <dynamics damping="0.5" />
  </joint>
  <link name="iiwa_link_4">
    <inertial>
      <origin rpy="0 0 0" xyz="0 0.067 0.034" />
      <mass value="3.5" />
      <inertia ixx="0.017" ixy="0" ixz="0" iyy="0.0164" iyz="0" izz="0.006" />
    </inertial>
    <visual name="iiwa_link_4_visual">
      <origin rpy="0 0 0" xyz="0 0 0" />
      <geometry>
        <mesh filename="package://drake/manipulation/models/iiwa_description/meshes/visual/link_4_orange.obj" />
      </geometry>
      <material name="Orange" />
    </visual>
    <visual name="iiwa_link_4_visual">
      <origin rpy="0 0 0" xyz="0 0 0" />
      <geometry>
        <mesh filename="package://drake/manipulation/models/iiwa_description/meshes/visual/link_4_grey.obj" />
      </geometry>
      <material name="Grey" />
    </visual>
  </link>
  <joint name="iiwa_joint_5" type="revolute">
    <parent link="iiwa_link_4" />
    <child link="iiwa_link_5" />
    <origin rpy="-1.570796326794897 3.141592653589793 0" xyz="0 0.1845 0" />
    <axis xyz="0 0 1" />
    <limit ns0:acceleration="12.23" effort="110" lower="-2.96705972839" upper="2.96705972839" velocity="2.2689280275926285" />
    <dynamics damping="0.5" />
  </joint>
  <link name="iiwa_link_5">
    <inertial>
      <origin rpy="0 0 0" xyz="0.0001 0.021 0.076" />
      <mass value="3.5" />
      <inertia ixx="0.01" ixy="0" ixz="0" iyy="0.0087" iyz="0" izz="0.00449" />
    </inertial>
    <visual name="iiwa_link_5_visual">
      <origin rpy="0 0 0" xyz="0 0 0" />
      <geometry>
        <mesh filename="package://drake/manipulation/models/iiwa_description/meshes/visual/link_5.obj" />
      </geometry>
      <material name="Grey" />
    </visual>
    <visual name="iiwa_link_5_visual">
      <origin rpy="0 0 0" xyz="0 0 0" />
      <geometry>
        <mesh filename="package://drake/manipulation/models/iiwa_description/meshes/visual/kuka.obj" />
      </geometry>
      <material name="Black" />
    </visual>
    <visual name="iiwa_link_5_visual">
      <origin rpy="0 0 0" xyz="0 0 0" />
      <geometry>
        <mesh filename="package://drake/manipulation/models/iiwa_description/meshes/visual/band.obj" />
      </geometry>
      <material name="Silver" />
    </visual>
  </link>
  <joint name="iiwa_joint_6" type="revolute">
    <parent link="iiwa_link_5" />
    <child link="iiwa_link_6" />
    <origin rpy="1.570796326794897 0 0" xyz="0 0 0.2155" />
    <axis xyz="0 0 1" />
    <limit ns0:acceleration="15.72" effort="40" lower="-2.09439510239" upper="2.09439510239" velocity="2.356194490192345" />
    <dynamics damping="0.5" />
  </joint>
  <link name="iiwa_link_6">
    <inertial>
      <origin rpy="0 0 0" xyz="0 0.0006 0.0004" />
      <mass value="1.8" />
      <inertia ixx="0.0049" ixy="0" ixz="0" iyy="0.0047" iyz="0" izz="0.0036" />
    </inertial>
    <visual name="iiwa_link_6_visual">
      <origin rpy="0 0 0" xyz="0 0 0" />
      <geometry>
        <mesh filename="package://drake/manipulation/models/iiwa_description/meshes/visual/link_6_grey.obj" />
      </geometry>
      <material name="Grey" />
    </visual>
    <visual name="iiwa_link_6_visual">
      <origin rpy="0 0 0" xyz="0 0 0" />
      <geometry>
        <mesh filename="package://drake/manipulation/models/iiwa_description/meshes/visual/link_6_orange.obj" />
      </geometry>
      <material name="Orange" />
    </visual>
  </link>
  <joint name="iiwa_joint_7" type="revolute">
    <parent link="iiwa_link_6" />
    <child link="iiwa_link_7" />
    <origin rpy="-1.570796326794897 3.141592653589793 0" xyz="0 0.081 0" />
    <axis xyz="0 0 1" />
    <limit ns0:acceleration="15.72" effort="40" lower="-3.05432619099" upper="3.05432619099" velocity="2.356194490192345" />
    <dynamics damping="0.5" />
  </joint>
  <link name="iiwa_link_7">
    <inertial>
      <origin rpy="0 0 0" xyz="0 0 0.02" />
      <mass value="1.2" />
      <inertia ixx="0.001" ixy="0" ixz="0" iyy="0.001" iyz="0" izz="0.001" />
    </inertial>
    <visual name="iiwa_link_7_visual">
      <origin rpy="0 0 0" xyz="0 0 0" />
      <geometry>
        <mesh filename="package://drake/manipulation/models/iiwa_description/meshes/visual/link_7.obj" />
      </geometry>
      <material name="Grey" />
    </visual>
    <collision name="iiwa_link_7_collision">
      <geometry>
	    <box size="0.105708 0.105708 0.047012"/> 
      </geometry>
		<origin xyz = "0.0 0.0 0.022492" rpy="0 0 0" xyz="0 0 0" />
      <material name="Grey" />
    </collision>
  </link>
  <joint name="iiwa_joint_ee" type="fixed">
    <parent link="iiwa_link_7" />
    <child link="iiwa_link_ee_kuka" />
    <origin rpy="3.141592653589793 3.141592653589793 3.141592653589793" xyz="0 0 0.045" />
    <axis xyz="0 0 1" />
  </joint>
  <link name="iiwa_link_ee_kuka">
    </link>
  <joint name="tool0_joint" type="fixed">
    <parent link="iiwa_link_7" />
    <child link="iiwa_link_ee" />
    <origin rpy="0 -1.570796326794897 0" xyz="0 0 0.045" />
  </joint>
  <link name="iiwa_link_ee">
    </link>
  <frame link="iiwa_link_ee" name="iiwa_frame_ee" rpy="3.141592653589793 0 1.570796326794897" xyz="0.09 0 0" />
</robot>